Workbook

Sheet Léame
A1: Tinku — Modelo financiero (capítulo 5 y anexo II)
A3: Planilla vigente del modelo con el que se calcularon los indicadores del capítulo 5. Reproduce las tablas del anexo II con fórmulas: al cambiar un parámetro, todo se recalcula.
A4: Todos los montos están en dólares estadounidenses (USD) salvo que la columna diga ARS.
A6: Cómo se lee
A7: Texto azul: parámetro de entrada (se puede modificar). Celdas amarillas: supuestos clave del modelo.
A8: Texto negro: fórmula calculada en la misma hoja. Texto verde: valor tomado de otra hoja.
A10: Hojas
A11: Parámetros — supuestos del modelo con su origen (tabla de parámetros del anexo II).
A12: Inversión — inversión inicial del Año 0 (tabla de inversión del capítulo 5).
A13: Costos fijos — costos operativos mensuales y anuales (tabla de costos fijos del capítulo 5).
A14: Demanda — alumnos activos y sesiones anuales por escenario (tabla de demanda del capítulo 5).
A15: Fundador — horas y costo del tiempo del fundador en soporte, moderación y credenciales.
... A22: Los valores que anulan el VAN se calculan en forma cerrada (el VAN es lineal en el margen por sesión), por lo que no hace falta usar Buscar objetivo.

Sheet Parámetros
A1: Parámetros del modelo
A3: Parámetro | B3: Valor | C3: Unidad | D3: Origen
A4: Precio horario promedio | B4: 13392.43 | C4: ARS/hora | D4: Relevamiento de 414 avisos de Superprof (apéndice E)
A5: Duración media de la sesión | B5: 51 | C5: minutos | D5: Ecuación de duración media del capítulo 5
A6: Tipo de cambio | B6: 1535 | C6: ARS/USD | D6: BNA, 09/09/2026 (cotización vendedor); el mismo que usa el sistema para el piso de tarifa
A7: Ticket promedio por sesión | B7: =ROUND(PrecioHoraARS*DuracionMin/60/TipoCambio,2) -> 7.42 | C7: USD/sesión | D7: Ecuación del ticket: precio horario × 51/60 / tipo de cambio, redondeado a centavos
A8: Comisión de la plataforma | B8: 0.27 | C8: % | D8: Regla BR-PAG-01 (ADR-M5-05)
A9: Comisión de MercadoPago (a cargo del tutor) | B9: 0.0604 | C9: % | D9: Modelo de cobro A (ADR-M5-02); no es costo de la plataforma, solo afecta el neto del tutor
A10: Margen de la plataforma por sesión | B10: =Ticket*Comision -> 2.0034 | C10: USD/sesión | D10: Ticket × comisión
A11: Clases por alumno activo por mes | B11: 3 | C11: clases | D11: Supuesto del capítulo 5 (tabla de demanda)
A12: Tasa de descuento | B12: 0.15 | C12: anual en USD | D12: Sección de tasa de descuento del capítulo 5
A13: Inversión inicial (Año 0) | B13: =Inversión!F13 -> 10279 | C13: USD | D13: Hoja Inversión
A14: Inversión de la cota (tarifas de contratista) | B14: 25730 | C14: USD | D14: Versión anterior del capítulo 5: desarrollo valorizado a USD 50/30/15 por hora
A15: Piso de tarifa por hora | B15: 4 | C15: USD/hora | D15: Piso del sistema (BR-PAG-04): $6.140 al tipo de cambio de $1.535
A17: Costo del tiempo del fundador
A18: Parámetro | B18: Valor | C18: Unidad | D18: Origen
A19: Salario mensual de referencia | B19: 1316632 | C19: ARS/mes | D19: Administrativo A, CCT 130/75, octubre de 2026, jornada completa (básico + suma fija); iProfesional, 01/10/2026
A20: Horas mensuales de jornada completa | B20: =48*52/12 -> 208 | C20: horas | D20: 48 horas semanales (Ley 11.544, art. 1) × 52 / 12
A21: Factor de sueldo anual complementario | B21: =13/12 -> 1.0833333 | D21: Un sueldo más por año (Ley 20.744, art. 121)
A22: Valor hora del fundador | B22: =SalarioARS/HorasMes*FactorSAC/TipoCambio -> 4.4673996 | C22: USD/hora | D22: Salario / horas × factor SAC / tipo de cambio
A23: Consultas de soporte por sesión | B23: 0.05 | C23: por sesión | D23: Supuesto propio declarado en el capítulo 5
A24: Minutos por consulta | B24: 10 | C24: min | D24: Supuesto propio
A25: Disputas o reembolsos manuales por sesión | B25: 0.01 | C25: por sesión | D25: Supuesto propio declarado en el capítulo 5
A26: Minutos por disputa | B26: 20 | C26: min | D26: Supuesto propio
A27: Denuncias por sesión | B27: 0.005 | C27: por sesión | D27: Supuesto propio declarado en el capítulo 5
A28: Minutos por denuncia | B28: 45 | C28: min | D28: Supuesto propio
A29: Alumnos activos por tutor | B29: 4 | C29: alumnos | D29: Tutores activos = alumnos activos / 4
A30: Documentos por tutor por año | B30: 2 | C30: documentos | D30: CAP (vigencia de 12 meses) + credencial académica
A31: Minutos por documento revisado | B31: 15 | C31: min | D31: Supuesto propio
A32: Horas fijas de revisión de paneles y colas | B32: =52/12 -> 4.3333333 | C32: horas/mes | D32: 1 hora semanal
A34: Riesgo R-09: desarrollador rentado a jornada completa
A35: Parámetro | B35: Valor | C35: Unidad | D35: Origen
A36: Horas mensuales del desarrollador rentado | B36: 160 | C36: horas | D36: Mismo divisor que las tarifas de la tabla de inversión

Sheet Inversión
A1: Inversión inicial (Año 0)
A3: Categoría | B3: Concepto | C3: Cantidad | D3: Valor unitario (USD) | E3: Unidad | F3: Total (USD)
A4: Personal | B4: Senior — arquitectura, IA y WebRTC | C4: 192 | D4: =TarifaSenior -> 17 | E4: horas | F4: =C4*D4 -> 3264
A5: Personal | B5: Semi-senior — backend y pasarela de pagos | C5: 250 | D5: =TarifaSemiSenior -> 11 | E5: horas | F5: =C5*D5 -> 2750
A6: Personal | B6: Junior — frontend PWA e interfaz | C6: 250 | D6: =TarifaJunior -> 7 | E6: horas | F6: =C6*D6 -> 1750
A7: Personal | B7: Junior — UAT y pruebas | C7: 120 | D7: =TarifaJunior -> 7 | E7: horas | F7: =C7*D7 -> 840
A8: Infraestructura | B8: Servidor propio preexistente y capas gratuitas (LiveKit, GitHub) | C8: 6 | D8: 0 | E8: meses | F8: =C8*D8 -> 0
A9: Administrativo | B9: Registro de dominio | C9: 1 | D9: 15 | E9: año | F9: =C9*D9 -> 15
A10: Legal | B10: Asesoría en privacidad de datos y TyC | C10: 1 | D10: 800 | E10: único | F10: =C10*D10 -> 800
A11: Riesgo | B11: Contingencia por imprevistos (% del desarrollo) | C11: 0.1 | D11: =SUM(F4:F7) -> 8604 | E11: base | F11: =ROUND(C11*D11,0) -> 860
B13: Total inversión inicial | F13: =SUM(F4:F10)+F11 -> 10279
A15: Tarifas por hora del personal
A16: Perfil | B16: Mediana salarial bruta mensual (ARS) | C16: Horas/mes | D16: Tarifa (USD/hora)
A17: Senior | B17: 4100000 | C17: 160 | D17: =ROUND(B17/C17/TipoCambio,0) -> 17
A18: Semi-senior | B18: 2800000 | C18: 160 | D18: =ROUND(B18/C18/TipoCambio,0) -> 11
A19: Junior | B19: 1667500 | C19: 160 | D19: =ROUND(B19/C19/TipoCambio,0) -> 7
A20: Medianas de desarrolladores con dedicación completa, Encuesta de Sueldos 2026.1 de Sysarmy; ÷ 160 horas ÷ tipo de cambio, redondeadas a dólares enteros. No incluyen contribuciones patronales.

Sheet Costos fijos
A1: Costos fijos operativos
A3: Categoría | B3: Concepto (USD por mes) | C3: Año 1 | D3: Año 2 | E3: Año 3 | F3: Año 4 | G3: Año 5
A4: Infraestructura | B4: Servidor, base de datos y respaldos | C4: 45 | D4: 45 | E4: 50 | F4: 55 | G4: 60
A5: Infraestructura | B5: Transmisión de video (LiveKit) | C5: 60 | D5: 60 | E5: 65 | F5: 70 | G5: 75
A6: Administrativo | B6: Honorarios contables | C6: 150 | D6: 150 | E6: 150 | F6: 150 | G6: 150
A7: Administrativo | B7: Renovación de dominio | C7: 1.25 | D7: 1.25 | E7: 1.25 | F7: 1.25 | G7: 1.25
A8: Comercial | B8: Adquisición de usuarios | C8: 40 | D8: 50 | E8: 60 | F8: 70 | G8: 80
B10: Total mensual | C10: =SUM(C4:C8) -> 296.25 | D10: =SUM(D4:D8) -> 306.25 | E10: =SUM(E4:E8) -> 326.25 | F10: =SUM(F4:F8) -> 346.25 | G10: =SUM(G4:G8) -> 366.25
B11: Total anual | C11: =C10*12 -> 3555 | D11: =D10*12 -> 3675 | E11: =E10*12 -> 3915 | F11: =F10*12 -> 4155 | G11: =G10*12 -> 4395
A13: Fuente: tabla de costos fijos del capítulo 5.

Sheet Demanda
A1: Demanda por escenario
A3: Alumnos activos | B3: Año 1 | C3: Año 2 | D3: Año 3 | E3: Año 4 | F3: Año 5 | G3: Promedio
A4: Pesimista | B4: 130 | C4: 110 | D4: 160 | E4: 140 | F4: 190 | G4: =AVERAGE(B4:F4) -> 146
A5: Base | B5: 200 | C5: 260 | D5: 210 | E5: 290 | F5: 250 | G5: =AVERAGE(B5:F5) -> 242
A6: Optimista | B6: 280 | C6: 420 | D6: 340 | E6: 480 | F6: 400 | G6: =AVERAGE(B6:F6) -> 384
A8: Sesiones anuales | B8: Año 1 | C8: Año 2 | D8: Año 3 | E8: Año 4 | F8: Año 5 | G8: Promedio
A9: Pesimista | B9: =B4*ClasesMes*12 -> 4680 | C9: =C4*ClasesMes*12 -> 3960 | D9: =D4*ClasesMes*12 -> 5760 | E9: =E4*ClasesMes*12 -> 5040 | F9: =F4*ClasesMes*12 -> 6840 | G9: =AVERAGE(B9:F9) -> 5256
A10: Base | B10: =B5*ClasesMes*12 -> 7200 | C10: =C5*ClasesMes*12 -> 9360 | D10: =D5*ClasesMes*12 -> 7560 | E10: =E5*ClasesMes*12 -> 10440 | F10: =F5*ClasesMes*12 -> 9000 | G10: =AVERAGE(B10:F10) -> 8712
A11: Optimista | B11: =B6*ClasesMes*12 -> 10080 | C11: =C6*ClasesMes*12 -> 15120 | D11: =D6*ClasesMes*12 -> 12240 | E11: =E6*ClasesMes*12 -> 17280 | F11: =F6*ClasesMes*12 -> 14400 | G11: =AVERAGE(B11:F11) -> 13824
A13: Sesiones anuales = alumnos activos × clases por mes × 12. Fuente: tabla de demanda del capítulo 5.

Sheet Fundador
A1: Horas y costo del tiempo del fundador
A2: horas/mes = sesiones/mes × (tasa × minutos)/60 por tarea + tutores × documentos/12 × minutos/60 + horas fijas; costo anual = horas/mes × 12 × valor hora
A4: Escenario pesimista
A5: Concepto | B5: Año 1 | C5: Año 2 | D5: Año 3 | E5: Año 4 | F5: Año 5
A6: Sesiones por mes | B6: =Demanda!B4*ClasesMes -> 390 | C6: =Demanda!C4*ClasesMes -> 330 | D6: =Demanda!D4*ClasesMes -> 480 | E6: =Demanda!E4*ClasesMes -> 420 | F6: =Demanda!F4*ClasesMes -> 570
A7: Tutores activos | B7: =Demanda!B4/AlumnosPorTutor -> 32.5 | C7: =Demanda!C4/AlumnosPorTutor -> 27.5 | D7: =Demanda!D4/AlumnosPorTutor -> 40 | E7: =Demanda!E4/AlumnosPorTutor -> 35 | F7: =Demanda!F4/AlumnosPorTutor -> 47.5
A8: Horas de soporte | B8: =B6*TasaConsulta*MinConsulta/60 -> 3.25 | C8: =C6*TasaConsulta*MinConsulta/60 -> 2.75 | D8: =D6*TasaConsulta*MinConsulta/60 -> 4 | E8: =E6*TasaConsulta*MinConsulta/60 -> 3.5 | F8: =F6*TasaConsulta*MinConsulta/60 -> 4.75
A9: Horas de soporte financiero | B9: =B6*TasaDisputa*MinDisputa/60 -> 1.3 | C9: =C6*TasaDisputa*MinDisputa/60 -> 1.1 | D9: =D6*TasaDisputa*MinDisputa/60 -> 1.6 | E9: =E6*TasaDisputa*MinDisputa/60 -> 1.4 | F9: =F6*TasaDisputa*MinDisputa/60 -> 1.9
A10: Horas de moderación | B10: =B6*TasaDenuncia*MinDenuncia/60 -> 1.4625 | C10: =C6*TasaDenuncia*MinDenuncia/60 -> 1.2375 | D10: =D6*TasaDenuncia*MinDenuncia/60 -> 1.8 | E10: =E6*TasaDenuncia*MinDenuncia/60 -> 1.575 | F10: =F6*TasaDenuncia*MinDenuncia/60 -> 2.1375
A11: Horas de revisión de credenciales | B11: =B7*DocsPorTutor/12*MinDocumento/60 -> 1.3541667 | C11: =C7*DocsPorTutor/12*MinDocumento/60 -> 1.1458333 | D11: =D7*DocsPorTutor/12*MinDocumento/60 -> 1.6666667 | E11: =E7*DocsPorTutor/12*MinDocumento/60 -> 1.4583333 | F11: =F7*DocsPorTutor/12*MinDocumento/60 -> 1.9791667
A12: Horas fijas | B12: =HorasFijasMes -> 4.3333333 | C12: =HorasFijasMes -> 4.3333333 | D12: =HorasFijasMes -> 4.3333333 | E12: =HorasFijasMes -> 4.3333333 | F12: =HorasFijasMes -> 4.3333333
A13: Total horas por mes | B13: =SUM(B8:B12) -> 11.7 | C13: =SUM(C8:C12) -> 10.566667 | D13: =SUM(D8:D12) -> 13.4 | E13: =SUM(E8:E12) -> 12.266667 | F13: =SUM(F8:F12) -> 15.1
A14: Costo mensual (USD) | B14: =B13*ValorHoraUSD -> 52.268575 | C14: =C13*ValorHoraUSD -> 47.205522 | D14: =D13*ValorHoraUSD -> 59.863154 | E14: =E13*ValorHoraUSD -> 54.800101 | F14: =F13*ValorHoraUSD -> 67.457733
A15: Costo anual (USD) | B15: =B14*12 -> 627.2229 | C15: =C14*12 -> 566.46626 | D15: =D14*12 -> 718.35785 | E15: =E14*12 -> 657.60122 | F15: =F14*12 -> 809.4928
A17: Escenario base
A18: Concepto | B18: Año 1 | C18: Año 2 | D18: Año 3 | E18: Año 4 | F18: Año 5
A19: Sesiones por mes | B19: =Demanda!B5*ClasesMes -> 600 | C19: =Demanda!C5*ClasesMes -> 780 | D19: =Demanda!D5*ClasesMes -> 630 | E19: =Demanda!E5*ClasesMes -> 870 | F19: =Demanda!F5*ClasesMes -> 750
A20: Tutores activos | B20: =Demanda!B5/AlumnosPorTutor -> 50 | C20: =Demanda!C5/AlumnosPorTutor -> 65 | D20: =Demanda!D5/AlumnosPorTutor -> 52.5 | E20: =Demanda!E5/AlumnosPorTutor -> 72.5 | F20: =Demanda!F5/AlumnosPorTutor -> 62.5
A21: Horas de soporte | B21: =B19*TasaConsulta*MinConsulta/60 -> 5 | C21: =C19*TasaConsulta*MinConsulta/60 -> 6.5 | D21: =D19*TasaConsulta*MinConsulta/60 -> 5.25 | E21: =E19*TasaConsulta*MinConsulta/60 -> 7.25 | F21: =F19*TasaConsulta*MinConsulta/60 -> 6.25
A22: Horas de soporte financiero | B22: =B19*TasaDisputa*MinDisputa/60 -> 2 | C22: =C19*TasaDisputa*MinDisputa/60 -> 2.6 | D22: =D19*TasaDisputa*MinDisputa/60 -> 2.1 | E22: =E19*TasaDisputa*MinDisputa/60 -> 2.9 | F22: =F19*TasaDisputa*MinDisputa/60 -> 2.5
A23: Horas de moderación | B23: =B19*TasaDenuncia*MinDenuncia/60 -> 2.25 | C23: =C19*TasaDenuncia*MinDenuncia/60 -> 2.925 | D23: =D19*TasaDenuncia*MinDenuncia/60 -> 2.3625 | E23: =E19*TasaDenuncia*MinDenuncia/60 -> 3.2625 | F23: =F19*TasaDenuncia*MinDenuncia/60 -> 2.8125
A24: Horas de revisión de credenciales | B24: =B20*DocsPorTutor/12*MinDocumento/60 -> 2.0833333 | C24: =C20*DocsPorTutor/12*MinDocumento/60 -> 2.7083333 | D24: =D20*DocsPorTutor/12*MinDocumento/60 -> 2.1875 | E24: =E20*DocsPorTutor/12*MinDocumento/60 -> 3.0208333 | F24: =F20*DocsPorTutor/12*MinDocumento/60 -> 2.6041667
A25: Horas fijas | B25: =HorasFijasMes -> 4.3333333 | C25: =HorasFijasMes -> 4.3333333 | D25: =HorasFijasMes -> 4.3333333 | E25: =HorasFijasMes -> 4.3333333 | F25: =HorasFijasMes -> 4.3333333
A26: Total horas por mes | B26: =SUM(B21:B25) -> 15.666667 | C26: =SUM(C21:C25) -> 19.066667 | D26: =SUM(D21:D25) -> 16.233333 | E26: =SUM(E21:E25) -> 20.766667 | F26: =SUM(F21:F25) -> 18.5
A27: Costo mensual (USD) | B27: =B26*ValorHoraUSD -> 69.98926 | C27: =C26*ValorHoraUSD -> 85.178418 | D27: =D26*ValorHoraUSD -> 72.520786 | E27: =E26*ValorHoraUSD -> 92.772998 | F27: =F26*ValorHoraUSD -> 82.646892
A28: Costo anual (USD) | B28: =B27*12 -> 839.87112 | C28: =C27*12 -> 1022.141 | D28: =D27*12 -> 870.24944 | E28: =E27*12 -> 1113.276 | F28: =F27*12 -> 991.7627
A30: Escenario optimista
A31: Concepto | B31: Año 1 | C31: Año 2 | D31: Año 3 | E31: Año 4 | F31: Año 5
A32: Sesiones por mes | B32: =Demanda!B6*ClasesMes -> 840 | C32: =Demanda!C6*ClasesMes -> 1260 | D32: =Demanda!D6*ClasesMes -> 1020 | E32: =Demanda!E6*ClasesMes -> 1440 | F32: =Demanda!F6*ClasesMes -> 1200
A33: Tutores activos | B33: =Demanda!B6/AlumnosPorTutor -> 70 | C33: =Demanda!C6/AlumnosPorTutor -> 105 | D33: =Demanda!D6/AlumnosPorTutor -> 85 | E33: =Demanda!E6/AlumnosPorTutor -> 120 | F33: =Demanda!F6/AlumnosPorTutor -> 100
A34: Horas de soporte | B34: =B32*TasaConsulta*MinConsulta/60 -> 7 | C34: =C32*TasaConsulta*MinConsulta/60 -> 10.5 | D34: =D32*TasaConsulta*MinConsulta/60 -> 8.5 | E34: =E32*TasaConsulta*MinConsulta/60 -> 12 | F34: =F32*TasaConsulta*MinConsulta/60 -> 10
A35: Horas de soporte financiero | B35: =B32*TasaDisputa*MinDisputa/60 -> 2.8 | C35: =C32*TasaDisputa*MinDisputa/60 -> 4.2 | D35: =D32*TasaDisputa*MinDisputa/60 -> 3.4 | E35: =E32*TasaDisputa*MinDisputa/60 -> 4.8 | F35: =F32*TasaDisputa*MinDisputa/60 -> 4
A36: Horas de moderación | B36: =B32*TasaDenuncia*MinDenuncia/60 -> 3.15 | C36: =C32*TasaDenuncia*MinDenuncia/60 -> 4.725 | D36: =D32*TasaDenuncia*MinDenuncia/60 -> 3.825 | E36: =E32*TasaDenuncia*MinDenuncia/60 -> 5.4 | F36: =F32*TasaDenuncia*MinDenuncia/60 -> 4.5
A37: Horas de revisión de credenciales | B37: =B33*DocsPorTutor/12*MinDocumento/60 -> 2.9166667 | C37: =C33*DocsPorTutor/12*MinDocumento/60 -> 4.375 | D37: =D33*DocsPorTutor/12*MinDocumento/60 -> 3.5416667 | E37: =E33*DocsPorTutor/12*MinDocumento/60 -> 5 | F37: =F33*DocsPorTutor/12*MinDocumento/60 -> 4.1666667
A38: Horas fijas | B38: =HorasFijasMes -> 4.3333333 | C38: =HorasFijasMes -> 4.3333333 | D38: =HorasFijasMes -> 4.3333333 | E38: =HorasFijasMes -> 4.3333333 | F38: =HorasFijasMes -> 4.3333333
A39: Total horas por mes | B39: =SUM(B34:B38) -> 20.2 | C39: =SUM(C34:C38) -> 28.133333 | D39: =SUM(D34:D38) -> 23.6 | E39: =SUM(E34:E38) -> 31.533333 | F39: =SUM(F34:F38) -> 27
A40: Costo mensual (USD) | B40: =B39*ValorHoraUSD -> 90.241471 | C40: =C39*ValorHoraUSD -> 125.68284 | D40: =D39*ValorHoraUSD -> 105.43063 | E40: =E39*ValorHoraUSD -> 140.872 | F40: =F39*ValorHoraUSD -> 120.61979
A41: Costo anual (USD) | B41: =B40*12 -> 1082.8977 | C41: =C40*12 -> 1508.1941 | D41: =D40*12 -> 1265.1676 | E41: =E40*12 -> 1690.464 | F41: =F40*12 -> 1447.4375

Sheet Flujos
A1: Flujos netos e indicadores por escenario (USD)
A2: VAN = Σ flujo_t / (1 + tasa)^t; TIR con IRR; repago = año previo al cruce + saldo pendiente / flujo del año del cruce (simple sobre flujos, descontado sobre flujos descontados).
A4: Escenario pesimista
A5: Concepto | B5: Año 0 | C5: Año 1 | D5: Año 2 | E5: Año 3 | F5: Año 4 | G5: Año 5
A6: Sesiones anuales | C6: =Demanda!B9 -> 4680 | D6: =Demanda!C9 -> 3960 | E6: =Demanda!D9 -> 5760 | F6: =Demanda!E9 -> 5040 | G6: =Demanda!F9 -> 6840
A7: Ingreso neto (sesiones × margen) | C7: =C6*Margen -> 9375.912 | D7: =D6*Margen -> 7933.464 | E7: =E6*Margen -> 11539.584 | F7: =F6*Margen -> 10097.136 | G7: =G6*Margen -> 13703.256
A8: Costos fijos anuales | C8: ='Costos fijos'!C11 -> 3555 | D8: ='Costos fijos'!D11 -> 3675 | E8: ='Costos fijos'!E11 -> 3915 | F8: ='Costos fijos'!F11 -> 4155 | G8: ='Costos fijos'!G11 -> 4395
A9: Costo del tiempo del fundador | C9: =Fundador!B15 -> 627.2229 | D9: =Fundador!C15 -> 566.46626 | E9: =Fundador!D15 -> 718.35785 | F9: =Fundador!E15 -> 657.60122 | G9: =Fundador!F15 -> 809.4928
A11: Flujo neto sin costo del fundador | B11: =-Inversion -> -10279 | C11: =C7-C8 -> 5820.912 | D11: =D7-D8 -> 4258.464 | E11: =E7-E8 -> 7624.584 | F11: =F7-F8 -> 5942.136 | G11: =G7-G8 -> 9308.256
A12: acumulado | B12: =B11 -> -10279 | C12: =B12+C11 -> -4458.088 | D12: =C12+D11 -> -199.624 | E12: =D12+E11 -> 7424.96 | F12: =E12+F11 -> 13367.096 | G12: =F12+G11 -> 22675.352
A13: cruce (repago simple) | C13: =IF(AND(B12<0,C12>=0),0+ABS(B12)/C11,"") | D13: =IF(AND(C12<0,D12>=0),1+ABS(C12)/D11,"") | E13: =IF(AND(D12<0,E12>=0),2+ABS(D12)/E11,"") -> 2.0261816 | F13: =IF(AND(E12<0,F12>=0),3+ABS(E12)/F11,"") | G13: =IF(AND(F12<0,G12>=0),4+ABS(F12)/G11,"")
A14: flujo descontado | B14: =B11/(1+Tasa)^0 -> -10279 | C14: =C11/(1+Tasa)^1 -> 5061.6626 | D14: =D11/(1+Tasa)^2 -> 3220.0106 | E14: =E11/(1+Tasa)^3 -> 5013.2877 | F14: =F11/(1+Tasa)^4 -> 3397.4355 | G14: =G11/(1+Tasa)^5 -> 4627.8483
A15: acumulado descontado | B15: =B14 -> -10279 | C15: =B15+C14 -> -5217.3374 | D15: =C15+D14 -> -1997.3268 | E15: =D15+E14 -> 3015.9609 | F15: =E15+F14 -> 6413.3965 | G15: =F15+G14 -> 11041.245
A16: cruce (repago descontado) | C16: =IF(AND(B15<0,C15>=0),0+ABS(B15)/C14,"") | D16: =IF(AND(C15<0,D15>=0),1+ABS(C15)/D14,"") | E16: =IF(AND(D15<0,E15>=0),2+ABS(D15)/E14,"") -> 2.3984066 | F16: =IF(AND(E15<0,F15>=0),3+ABS(E15)/F14,"") | G16: =IF(AND(F15<0,G15>=0),4+ABS(F15)/G14,"")
A18: Flujo neto con costo del fundador | B18: =-Inversion -> -10279 | C18: =C7-C8-1*C9 -> 5193.6891 | D18: =D7-D8-1*D9 -> 3691.9977 | E18: =E7-E8-1*E9 -> 6906.2261 | F18: =F7-F8-1*F9 -> 5284.5348 | G18: =G7-G8-1*G9 -> 8498.7632
A19: acumulado | B19: =B18 -> -10279 | C19: =B19+C18 -> -5085.3109 | D19: =C19+D18 -> -1393.3132 | E19: =D19+E18 -> 5512.913 | F19: =E19+F18 -> 10797.448 | G19: =F19+G18 -> 19296.211
A20: cruce (repago simple) | C20: =IF(AND(B19<0,C19>=0),0+ABS(B19)/C18,"") | D20: =IF(AND(C19<0,D19>=0),1+ABS(C19)/D18,"") | E20: =IF(AND(D19<0,E19>=0),2+ABS(D19)/E18,"") -> 2.2017474 | F20: =IF(AND(E19<0,F19>=0),3+ABS(E19)/F18,"") | G20: =IF(AND(F19<0,G19>=0),4+ABS(F19)/G18,"")
A21: flujo descontado | B21: =B18/(1+Tasa)^0 -> -10279 | C21: =C18/(1+Tasa)^1 -> 4516.2514 | D21: =D18/(1+Tasa)^2 -> 2791.6807 | E21: =E18/(1+Tasa)^3 -> 4540.9558 | F21: =F18/(1+Tasa)^4 -> 3021.4499 | G21: =G18/(1+Tasa)^5 -> 4225.3873
A22: acumulado descontado | B22: =B21 -> -10279 | C22: =B22+C21 -> -5762.7486 | D22: =C22+D21 -> -2971.0679 | E22: =D22+E21 -> 1569.8879 | F22: =E22+F21 -> 4591.3378 | G22: =F22+G21 -> 8816.7252
A23: cruce (repago descontado) | C23: =IF(AND(B22<0,C22>=0),0+ABS(B22)/C21,"") | D23: =IF(AND(C22<0,D22>=0),1+ABS(C22)/D21,"") | E23: =IF(AND(D22<0,E22>=0),2+ABS(D22)/E21,"") -> 2.6542825 | F23: =IF(AND(E22<0,F22>=0),3+ABS(E22)/F21,"") | G23: =IF(AND(F22<0,G22>=0),4+ABS(F22)/G21,"")
A25: Flujo neto con el doble de horas | B25: =-Inversion -> -10279 | C25: =C7-C8-2*C9 -> 4566.4662 | D25: =D7-D8-2*D9 -> 3125.5315 | E25: =E7-E8-2*E9 -> 6187.8683 | F25: =F7-F8-2*F9 -> 4626.9336 | G25: =G7-G8-2*G9 -> 7689.2704
A26: acumulado | B26: =B25 -> -10279 | C26: =B26+C25 -> -5712.5338 | D26: =C26+D25 -> -2587.0023 | E26: =D26+E25 -> 3600.866 | F26: =E26+F25 -> 8227.7995 | G26: =F26+G25 -> 15917.07
A27: cruce (repago simple) | C27: =IF(AND(B26<0,C26>=0),0+ABS(B26)/C25,"") | D27: =IF(AND(C26<0,D26>=0),1+ABS(C26)/D25,"") | E27: =IF(AND(D26<0,E26>=0),2+ABS(D26)/E25,"") -> 2.4180765 | F27: =IF(AND(E26<0,F26>=0),3+ABS(E26)/F25,"") | G27: =IF(AND(F26<0,G26>=0),4+ABS(F26)/G25,"")
A28: flujo descontado | B28: =B25/(1+Tasa)^0 -> -10279 | C28: =C25/(1+Tasa)^1 -> 3970.8402 | D28: =D25/(1+Tasa)^2 -> 2363.3508 | E28: =E25/(1+Tasa)^3 -> 4068.6239 | F28: =F25/(1+Tasa)^4 -> 2645.4643 | G28: =G25/(1+Tasa)^5 -> 3822.9264
A29: acumulado descontado | B29: =B28 -> -10279 | C29: =B29+C28 -> -6308.1598 | D29: =C29+D28 -> -3944.809 | E29: =D29+E28 -> 123.81485 | F29: =E29+F28 -> 2769.2791 | G29: =F29+G28 -> 6592.2055
A30: cruce (repago descontado) | C30: =IF(AND(B29<0,C29>=0),0+ABS(B29)/C28,"") | D30: =IF(AND(C29<0,D29>=0),1+ABS(C29)/D28,"") | E30: =IF(AND(D29<0,E29>=0),2+ABS(D29)/E28,"") -> 2.9695684 | F30: =IF(AND(E29<0,F29>=0),3+ABS(E29)/F28,"") | G30: =IF(AND(F29<0,G29>=0),4+ABS(F29)/G28,"")
A33: Escenario base
A34: Concepto | B34: Año 0 | C34: Año 1 | D34: Año 2 | E34: Año 3 | F34: Año 4 | G34: Año 5
A35: Sesiones anuales | C35: =Demanda!B10 -> 7200 | D35: =Demanda!C10 -> 9360 | E35: =Demanda!D10 -> 7560 | F35: =Demanda!E10 -> 10440 | G35: =Demanda!F10 -> 9000
A36: Ingreso neto (sesiones × margen) | C36: =C35*Margen -> 14424.48 | D36: =D35*Margen -> 18751.824 | E36: =E35*Margen -> 15145.704 | F36: =F35*Margen -> 20915.496 | G36: =G35*Margen -> 18030.6
A37: Costos fijos anuales | C37: ='Costos fijos'!C11 -> 3555 | D37: ='Costos fijos'!D11 -> 3675 | E37: ='Costos fijos'!E11 -> 3915 | F37: ='Costos fijos'!F11 -> 4155 | G37: ='Costos fijos'!G11 -> 4395
A38: Costo del tiempo del fundador | C38: =Fundador!B28 -> 839.87112 | D38: =Fundador!C28 -> 1022.141 | E38: =Fundador!D28 -> 870.24944 | F38: =Fundador!E28 -> 1113.276 | G38: =Fundador!F28 -> 991.7627
A40: Flujo neto sin costo del fundador | B40: =-Inversion -> -10279 | C40: =C36-C37 -> 10869.48 | D40: =D36-D37 -> 15076.824 | E40: =E36-E37 -> 11230.704 | F40: =F36-F37 -> 16760.496 | G40: =G36-G37 -> 13635.6
A41: acumulado | B41: =B40 -> -10279 | C41: =B41+C40 -> 590.48 | D41: =C41+D40 -> 15667.304 | E41: =D41+E40 -> 26898.008 | F41: =E41+F40 -> 43658.504 | G41: =F41+G40 -> 57294.104
A42: cruce (repago simple) | C42: =IF(AND(B41<0,C41>=0),0+ABS(B41)/C40,"") -> 0.94567541 | D42: =IF(AND(C41<0,D41>=0),1+ABS(C41)/D40,"") | E42: =IF(AND(D41<0,E41>=0),2+ABS(D41)/E40,"") | F42: =IF(AND(E41<0,F41>=0),3+ABS(E41)/F40,"") | G42: =IF(AND(F41<0,G41>=0),4+ABS(F41)/G40,"")
A43: flujo descontado | B43: =B40/(1+Tasa)^0 -> -10279 | C43: =C40/(1+Tasa)^1 -> 9451.7217 | D43: =D40/(1+Tasa)^2 -> 11400.245 | E43: =E40/(1+Tasa)^3 -> 7384.3702 | F43: =F40/(1+Tasa)^4 -> 9582.868 | G43: =G40/(1+Tasa)^5 -> 6779.3031
A44: acumulado descontado | B44: =B43 -> -10279 | C44: =B44+C43 -> -827.27826 | D44: =C44+D43 -> 10572.967 | E44: =D44+E43 -> 17957.337 | F44: =E44+F43 -> 27540.205 | G44: =F44+G43 -> 34319.508
A45: cruce (repago descontado) | C45: =IF(AND(B44<0,C44>=0),0+ABS(B44)/C43,"") | D45: =IF(AND(C44<0,D44>=0),1+ABS(C44)/D43,"") -> 1.0725667 | E45: =IF(AND(D44<0,E44>=0),2+ABS(D44)/E43,"") | F45: =IF(AND(E44<0,F44>=0),3+ABS(E44)/F43,"") | G45: =IF(AND(F44<0,G44>=0),4+ABS(F44)/G43,"")
A47: Flujo neto con costo del fundador | B47: =-Inversion -> -10279 | C47: =C36-C37-1*C38 -> 10029.609 | D47: =D36-D37-1*D38 -> 14054.683 | E47: =E36-E37-1*E38 -> 10360.455 | F47: =F36-F37-1*F38 -> 15647.22 | G47: =G36-G37-1*G38 -> 12643.837
A48: acumulado | B48: =B47 -> -10279 | C48: =B48+C47 -> -249.39112 | D48: =C48+D47 -> 13805.292 | E48: =D48+E47 -> 24165.746 | F48: =E48+F47 -> 39812.966 | G48: =F48+G47 -> 52456.804
...

Sheet Indicadores
A1: Indicadores por escenario
A3: Escenario | B3: Variante | C3: VAN (USD) | D3: TIR | E3: Repago simple | F3: Repago descontado
A4: Pesimista | B4: Sin costo del fundador | C4: =NPV(Tasa,Flujos!C11:G11)+Flujos!B11 -> 11041.245 | D4: =IFERROR(IF(IRR(Flujos!B11:G11,0)<-0.99,IRR(Flujos!B11:G11,-0.5),IRR(Flujos!B11:G11,0)),"no existe") -> 0.5091961 | E4: =IF(COUNT(Flujos!C13:G13)=0,"no",MIN(Flujos!C13:G13)) -> 2.0261816 | F4: =IF(COUNT(Flujos!C16:G16)=0,"no",MIN(Flujos!C16:G16)) -> 2.3984066
B5: Con costo del fundador | C5: =NPV(Tasa,Flujos!C18:G18)+Flujos!B18 -> 8816.7252 | D5: =IFERROR(IF(IRR(Flujos!B18:G18,0)<-0.99,IRR(Flujos!B18:G18,-0.5),IRR(Flujos!B18:G18,0)),"no existe") -> 0.44126511 | E5: =IF(COUNT(Flujos!C20:G20)=0,"no",MIN(Flujos!C20:G20)) -> 2.2017474 | F5: =IF(COUNT(Flujos!C23:G23)=0,"no",MIN(Flujos!C23:G23)) -> 2.6542825
B6: Con el doble de horas | C6: =NPV(Tasa,Flujos!C25:G25)+Flujos!B25 -> 6592.2055 | D6: =IFERROR(IF(IRR(Flujos!B25:G25,0)<-0.99,IRR(Flujos!B25:G25,-0.5),IRR(Flujos!B25:G25,0)),"no existe") -> 0.37165224 | E6: =IF(COUNT(Flujos!C27:G27)=0,"no",MIN(Flujos!C27:G27)) -> 2.4180765 | F6: =IF(COUNT(Flujos!C30:G30)=0,"no",MIN(Flujos!C30:G30)) -> 2.9695684
A7: Base | B7: Sin costo del fundador | C7: =NPV(Tasa,Flujos!C40:G40)+Flujos!B40 -> 34319.508 | D7: =IFERROR(IF(IRR(Flujos!B40:G40,0)<-0.99,IRR(Flujos!B40:G40,-0.5),IRR(Flujos!B40:G40,0)),"no existe") -> 1.1779916 | E7: =IF(COUNT(Flujos!C42:G42)=0,"no",MIN(Flujos!C42:G42)) -> 0.94567541 | F7: =IF(COUNT(Flujos!C45:G45)=0,"no",MIN(Flujos!C45:G45)) -> 1.0725667
B8: Con costo del fundador | C8: =NPV(Tasa,Flujos!C47:G47)+Flujos!B47 -> 31114.496 | D8: =IFERROR(IF(IRR(Flujos!B47:G47,0)<-0.99,IRR(Flujos!B47:G47,-0.5),IRR(Flujos!B47:G47,0)),"no existe") -> 1.0910103 | E8: =IF(COUNT(Flujos!C49:G49)=0,"no",MIN(Flujos!C49:G49)) -> 1.0177443 | F8: =IF(COUNT(Flujos!C52:G52)=0,"no",MIN(Flujos!C52:G52)) -> 1.1465652
B9: Con el doble de horas | C9: =NPV(Tasa,Flujos!C54:G54)+Flujos!B54 -> 27909.484 | D9: =IFERROR(IF(IRR(Flujos!B54:G54,0)<-0.99,IRR(Flujos!B54:G54,-0.5),IRR(Flujos!B54:G54,0)),"no existe") -> 1.0032672 | E9: =IF(COUNT(Flujos!C56:G56)=0,"no",MIN(Flujos!C56:G56)) -> 1.0835802 | F9: =IF(COUNT(Flujos!C59:G59)=0,"no",MIN(Flujos!C59:G59)) -> 1.2321711
A10: Optimista | B10: Sin costo del fundador | C10: =NPV(Tasa,Flujos!C69:G69)+Flujos!B69 -> 67440.634 | D10: =IFERROR(IF(IRR(Flujos!B69:G69,0)<-0.99,IRR(Flujos!B69:G69,-0.5),IRR(Flujos!B69:G69,0)),"no existe") -> 1.9031564 | E10: =IF(COUNT(Flujos!C71:G71)=0,"no",MIN(Flujos!C71:G71)) -> 0.61775539 | F10: =IF(COUNT(Flujos!C74:G74)=0,"no",MIN(Flujos!C74:G74)) -> 0.7104187
B11: Con costo del fundador | C11: =NPV(Tasa,Flujos!C76:G76)+Flujos!B76 -> 62840.544 | D11: =IFERROR(IF(IRR(Flujos!B76:G76,0)<-0.99,IRR(Flujos!B76:G76,-0.5),IRR(Flujos!B76:G76,0)),"no existe") -> 1.7938651 | E11: =IF(COUNT(Flujos!C78:G78)=0,"no",MIN(Flujos!C78:G78)) -> 0.66075808 | F11: =IF(COUNT(Flujos!C81:G81)=0,"no",MIN(Flujos!C81:G81)) -> 0.75987179
B12: Con el doble de horas | C12: =NPV(Tasa,Flujos!C83:G83)+Flujos!B83 -> 58240.454 | D12: =IFERROR(IF(IRR(Flujos!B83:G83,0)<-0.99,IRR(Flujos!B83:G83,-0.5),IRR(Flujos!B83:G83,0)),"no existe") -> 1.6841637 | E12: =IF(COUNT(Flujos!C85:G85)=0,"no",MIN(Flujos!C85:G85)) -> 0.71019564 | F12: =IF(COUNT(Flujos!C88:G88)=0,"no",MIN(Flujos!C88:G88)) -> 0.81672498
A14: Las filas «sin costo del fundador» corresponden a la tabla de indicadores del anexo II; las tres variantes, a la tabla del VAN con y sin el costo del fundador.

Sheet Sensibilidad
A1: Análisis de sensibilidad (escenario base salvo indicación)
A2: El VAN es lineal en el margen m: VAN(m) = m × VA(sesiones) − inversión − VA(costos fijos). Los valores que lo anulan se despejan de esa ecuación.
A4: Valor presente (Años 1 a 5) | B4: Año 1 | C4: Año 2 | D4: Año 3 | E4: Año 4 | F4: Año 5 | G4: Suma
A5: Factor de descuento | B5: =1/(1+Tasa)^1 -> 0.86956522 | C5: =1/(1+Tasa)^2 -> 0.75614367 | D5: =1/(1+Tasa)^3 -> 0.65751623 | E5: =1/(1+Tasa)^4 -> 0.57175325 | F5: =1/(1+Tasa)^5 -> 0.49717674 | G5: =SUM(B5:F5) -> 3.3521551
A6: Costos fijos anuales | B6: ='Costos fijos'!C11 -> 3555 | C6: ='Costos fijos'!D11 -> 3675 | D6: ='Costos fijos'!E11 -> 3915 | E6: ='Costos fijos'!F11 -> 4155 | F6: ='Costos fijos'!G11 -> 4395 | G6: =SUMPRODUCT(B6:F6,B5:F5) -> 13005.035
A7: Sesiones anuales, base | B7: =Demanda!B10 -> 7200 | C7: =Demanda!C10 -> 9360 | D7: =Demanda!D10 -> 7560 | E7: =Demanda!E10 -> 10440 | F7: =Demanda!F10 -> 9000 | G7: =SUMPRODUCT(B7:F7,B5:F5) -> 28752.892
A8: Sesiones anuales, pesimista | B8: =Demanda!B9 -> 4680 | C8: =Demanda!C9 -> 3960 | D8: =Demanda!D9 -> 5760 | E8: =Demanda!E9 -> 5040 | F8: =Demanda!F9 -> 6840 | G8: =SUMPRODUCT(B8:F8,B5:F5) -> 17133.513
A10: Valor que anula el VAN | B10: Valor | C10: Unidad
A11: Margen por sesión, base | B11: =(Inversion+VACostos)/VASesBase -> 0.80979803 | C11: USD/sesión
A12: Comisión, base | B12: =MargenEq/Ticket -> 0.1091372 | C12: %
A13: Comisión, pesimista | B13: =(Inversion+VACostos)/VASesPes/Ticket -> 0.18315042 | C13: %
A14: Ticket por sesión | B14: =MargenEq/Comision -> 2.999252 | C14: USD/sesión
A15: Ticket por hora | B15: =TicketEq*60/DuracionMin -> 3.5285317 | C15: USD/hora
A16: Ticket por hora en pesos | B16: =TicketEq*60/DuracionMin*TipoCambio -> 5416.2962 | C16: ARS/hora
A17: Tipo de cambio | B17: =PrecioHoraARS*DuracionMin/60/TicketEq -> 3795.4682 | C17: ARS/USD
A18: Caída del volumen de sesiones | B18: =1-MargenEq/Margen -> 0.59578815 | C18: %
A19: Sesiones anuales promedio | B19: =MargenEq/Margen*Demanda!G10 -> 3521.4937 | C19: sesiones
A20: Descuento medio de paquete | B20: =1-TicketEq/Ticket -> 0.59578815 | C20: %
A21: Duración media de la sesión | B21: =DuracionMin*MargenEq/Margen -> 20.614805 | C21: minutos
A22: Costo mensual constante adicional | B22: =(NPV(Tasa,Flujos!C40:G40)+Flujos!B40)/AnualidadVA/12 -> 853.17025 | C22: USD/mes
A23: equivalente en horas del fundador | B23: =ExcedenteMes/ValorHoraUSD -> 190.97693 | C23: horas/mes
A24: Inversión inicial, pesimista | B24: =NPV(Tasa,Flujos!C11:G11)+Flujos!B11+Inversion -> 21320.245 | C24: USD
A25: Inversión inicial, base | B25: =NPV(Tasa,Flujos!C40:G40)+Flujos!B40+Inversion -> 44598.508 | C25: USD
A26: Inversión inicial, optimista | B26: =NPV(Tasa,Flujos!C69:G69)+Flujos!B69+Inversion -> 77719.634 | C26: USD
A28: Ticket alternativo (escenario base) | B28: Ticket (USD) | C28: VAN base (USD)
A29: Todas las sesiones al piso de tarifa | B29: =PisoUSDHora*DuracionMin/60 -> 3.4 | C29: =B29*Comision*VASesBase-Inversion-VACostos -> 3111.1195
A30: Mitad de las sesiones en paquete con 30 % | B30: =Ticket*0.85 -> 6.307 | C30: =B30*Comision*VASesBase-Inversion-VACostos -> 25678.977
A31: Todas las sesiones en paquete con 30 % | B31: =Ticket*0.7 -> 5.194 | C31: =B31*Comision*VASesBase-Inversion-VACostos -> 17038.445
A32: Duración de 45 minutos | B32: =ROUND(PrecioHoraARS/TipoCambio*45/60,2) -> 6.54 | C32: =B32*Comision*VASesBase-Inversion-VACostos -> 27487.821
A33: Duración de 60 minutos | B33: =ROUND(PrecioHoraARS/TipoCambio*60/60,2) -> 8.72 | C33: =B33*Comision*VASesBase-Inversion-VACostos -> 44411.773
A35: Comisión de la plataforma
A36: Comisión | B36: Margen | C36: Año 0 | D36: Año 1 | E36: Año 2 | F36: Año 3 | G36: Año 4 | H36: Año 5 | I36: VAN base | J36: TIR base | K36: VAN pesimista | L36: Neto del tutor
A37: =MargenEq/Ticket -> 0.1091372 | B37: =Ticket*A37 -> 0.80979803 | C37: =-Inversion -> -10279 | D37: =Demanda!B10*B37-'Costos fijos'!C11 -> 2275.5458 | E37: =Demanda!C10*B37-'Costos fijos'!D11 -> 3904.7095 | F37: =Demanda!D10*B37-'Costos fijos'!E11 -> 2207.0731 | G37: =Demanda!E10*B37-'Costos fijos'!F11 -> 4299.2914 | H37: =Demanda!F10*B37-'Costos fijos'!G11 -> 2893.1823 | I37: =NPV(Tasa,D37:H37)+C37 -> 0 | J37: =IFERROR(IF(IRR(C37:H37,0)<-0.99,IRR(C37:H37,-0.5),IRR(C37:H37,0)),"no existe") -> 0.15 | K37: =B37*VASesPes-Inversion-VACostos -> -9409.3499 | L37: =1-A37-ComisionMP -> 0.8304628
A38: 0.21 | B38: =Ticket*A38 -> 1.5582 | C38: =-Inversion -> -10279 | D38: =Demanda!B10*B38-'Costos fijos'!C11 -> 7664.04 | E38: =Demanda!C10*B38-'Costos fijos'!D11 -> 10909.752 | F38: =Demanda!D10*B38-'Costos fijos'!E11 -> 7864.992 | G38: =Demanda!E10*B38-'Costos fijos'!F11 -> 12112.608 | H38: =Demanda!F10*B38-'Costos fijos'!G11 -> 9628.8 | I38: =NPV(Tasa,D38:H38)+C38 -> 21518.721 | J38: =IFERROR(IF(IRR(C38:H38,0)<-0.99,IRR(C38:H38,-0.5),IRR(C38:H38,0)),"no existe") -> 0.82993454 | K38: =B38*VASesPes-Inversion-VACostos -> 3413.4049 | L38: =1-A38-ComisionMP -> 0.7296
A39: 0.23 | B39: =Ticket*A39 -> 1.7066 | C39: =-Inversion -> -10279 | D39: =Demanda!B10*B39-'Costos fijos'!C11 -> 8732.52 | E39: =Demanda!C10*B39-'Costos fijos'!D11 -> 12298.776 | F39: =Demanda!D10*B39-'Costos fijos'!E11 -> 8986.896 | G39: =Demanda!E10*B39-'Costos fijos'!F11 -> 13661.904 | H39: =Demanda!F10*B39-'Costos fijos'!G11 -> 10964.4 | I39: =NPV(Tasa,D39:H39)+C39 -> 25785.65 | J39: =IFERROR(IF(IRR(C39:H39,0)<-0.99,IRR(C39:H39,-0.5),IRR(C39:H39,0)),"no existe") -> 0.94802211 | K39: =B39*VASesPes-Inversion-VACostos -> 5956.0182 | L39: =1-A39-ComisionMP -> 0.7096
A40: 0.25 | B40: =Ticket*A40 -> 1.855 | C40: =-Inversion -> -10279 | D40: =Demanda!B10*B40-'Costos fijos'!C11 -> 9801 | E40: =Demanda!C10*B40-'Costos fijos'!D11 -> 13687.8 | F40: =Demanda!D10*B40-'Costos fijos'!E11 -> 10108.8 | G40: =Demanda!E10*B40-'Costos fijos'!F11 -> 15211.2 | H40: =Demanda!F10*B40-'Costos fijos'!G11 -> 12300 | I40: =NPV(Tasa,D40:H40)+C40 -> 30052.579 | J40: =IFERROR(IF(IRR(C40:H40,0)<-0.99,IRR(C40:H40,-0.5),IRR(C40:H40,0)),"no existe") -> 1.0638692 | K40: =B40*VASesPes-Inversion-VACostos -> 8498.6315 | L40: =1-A40-ComisionMP -> 0.6896
A41: =Comision -> 0.27 | B41: =Ticket*A41 -> 2.0034 | C41: =-Inversion -> -10279 | D41: =Demanda!B10*B41-'Costos fijos'!C11 -> 10869.48 | E41: =Demanda!C10*B41-'Costos fijos'!D11 -> 15076.824 | F41: =Demanda!D10*B41-'Costos fijos'!E11 -> 11230.704 | G41: =Demanda!E10*B41-'Costos fijos'!F11 -> 16760.496 | H41: =Demanda!F10*B41-'Costos fijos'!G11 -> 13635.6 | I41: =NPV(Tasa,D41:H41)+C41 -> 34319.508 | J41: =IFERROR(IF(IRR(C41:H41,0)<-0.99,IRR(C41:H41,-0.5),IRR(C41:H41,0)),"no existe") -> 1.1779916 | K41: =B41*VASesPes-Inversion-VACostos -> 11041.245 | L41: =1-A41-ComisionMP -> 0.6696
A42: 0.3 | B42: =Ticket*A42 -> 2.226 | C42: =-Inversion -> -10279 | D42: =Demanda!B10*B42-'Costos fijos'!C11 -> 12472.2 | E42: =Demanda!C10*B42-'Costos fijos'!D11 -> 17160.36 | F42: =Demanda!D10*B42-'Costos fijos'!E11 -> 12913.56 | G42: =Demanda!E10*B42-'Costos fijos'!F11 -> 19084.44 | H42: =Demanda!F10*B42-'Costos fijos'!G11 -> 15639 | I42: =NPV(Tasa,D42:H42)+C42 -> 40719.902 | J42: =IFERROR(IF(IRR(C42:H42,0)<-0.99,IRR(C42:H42,-0.5),IRR(C42:H42,0)),"no existe") -> 1.3467211 | K42: =B42*VASesPes-Inversion-VACostos -> 14855.165 | L42: =1-A42-ComisionMP -> 0.6396
A43: 0.33 | B43: =Ticket*A43 -> 2.4486 | C43: =-Inversion -> -10279 | D43: =Demanda!B10*B43-'Costos fijos'!C11 -> 14074.92 | E43: =Demanda!C10*B43-'Costos fijos'!D11 -> 19243.896 | F43: =Demanda!D10*B43-'Costos fijos'!E11 -> 14596.416 | G43: =Demanda!E10*B43-'Costos fijos'!F11 -> 21408.384 | H43: =Demanda!F10*B43-'Costos fijos'!G11 -> 17642.4 | I43: =NPV(Tasa,D43:H43)+C43 -> 47120.295 | J43: =IFERROR(IF(IRR(C43:H43,0)<-0.99,IRR(C43:H43,-0.5),IRR(C43:H43,0)),"no existe") -> 1.513241 | K43: =B43*VASesPes-Inversion-VACostos -> 18669.085 | L43: =1-A43-ComisionMP -> 0.6096
A45: Tipo de cambio
...
