Workbook

Sheet Gráficos
B2: Gráficos - Proyecto Tinku

Sheet Inversión Inicial
B1: Categoría | C1: Item | D1: Detalle | E1: Unidad_o_Frecuencia | F1: Cantidad | G1: Valor_Unitario (USD) | H1: Total_Estimado (USD) | I1: Observaciones
B2: Personal | C2: Desarrollo pendiente (Senior, asistido con IA) | D2: 36 tareas x 0,76 h/tarea (103,2 h de git-hours / 136 tareas completadas) | E2: Horas | F2: =36*103.2/136 -> 27.317647 | G2: 50 | H2: =F2*G2 -> 1365.8824 | I2: 32 tareas pendientes del repo al 22/09/2026, más 5 para reincorporar el CAP para tutores de menores y menos 1 que se cancela (T-AUD-032). Tasa observada en el propio repositorio
B3: Personal | C3: Soporte y correcciones del piloto (Senior) | D3: 8 h/sem x 4 semanas (Sprint 11) | E3: Horas | F3: 32 | G3: 50 | H3: =F3*G3 -> 1600 | I3: Misma dedicación semanal que el perfil senior del modelo original
B4: Personal | C4: UAT del piloto (QA Junior) | D4: 5 h/sem x 4 semanas (Sprint 11) | E4: Horas | F4: 20 | G4: 15 | H4: =F4*G4 -> 300 | I4: Misma dedicación semanal que el perfil QA del modelo original
B5: Costo hundido | C5: MVP ya construido (no se imputa) | D5: 103,2 h según git-hours; ~10.300 h según COCOMO básico para 24.110 líneas | E5: Horas | F5: 103.2 | G5: 0 | H5: =F5*G5 -> 0 | I5: Costo hundido: ya incurrido, no depende de la decisión de lanzar. Se informa pero no integra la inversión
B6: Infraestructura | C6: Cloud MVP (Supabase/Vercel/LiveKit) | D6: Planes gratuitos de desarrollo | E6: 6 meses | F6: 1 | G6: 0 | H6: =F6*G6 -> 0 | I6: Capas Free Tier
B7: Administrativo | C7: Registro de Dominio | D7: tinku.site (Namecheap) | E7: 1 año | F7: 1 | G7: 3 | H7: =F7*G7 -> 3 | I7: Monto efectivamente pagado
B8: Costos Ocultos (Legal) | C8: Asesoría Legal (TyC y Privacidad) | D8: TyC, privacidad (Ley 25.326) y criterio de rechazo por antecedentes (CAP) | E8: Pago único | F8: 1 | G8: 800 | H8: =F8*G8 -> 800 | I8: Pago único
B9: Costos Ocultos (Riesgo) | C9: Contingencia por Imprevistos | D9: 10% del trabajo del lanzamiento | E9: 10% de H2:H4 | F9: 1 | G9: =0.1*SUM(H2:H4) -> 326.58824 | H9: =F9*G9 -> 326.58824 | I9: Retrabajo y subestimación de las tareas pendientes
C10: TOTAL INVERSIÓN INCREMENTAL | H10: =SUM(H2:H9) -> 4395.4706

Sheet Gastos Post-lanzamiento
B1: Categoría | C1: Item | D1: Detalle | E1: Año 1 (USD/mes) | F1: Año 2 (USD/mes) | G1: Año 3 (USD/mes) | H1: Año 4 (USD/mes) | I1: Año 5 (USD/mes) | J1: Observaciones
B2: Infraestructura | C2: Servidores y BD | D2: Supabase Pro + Vercel Pro | E2: 45 | F2: 45 | G2: 50 | H2: 55 | I2: 60 | J2: Escala apenas con volumen; la demanda no tiene tendencia sostenida de crecimiento
B3: Infraestructura | C3: Servidor de aplicación (VPS) | D3: DigitalOcean Basic 2 vCPU / 4 GB | E3: 24 | F3: 24 | G3: 24 | H3: 24 | I3: 24 | J3: Backend Spring Boot + matching-service. Planes económicos de Hetzner sin stock y con dos aumentos en 2026 (tarifa pública, sep-2026)
B4: Infraestructura | C4: Transmisión de Video (LiveKit) | D4: Tráfico de salida y ancho de banda | E4: 60 | F4: 60 | G4: 65 | H4: 70 | I4: 75 | J4: Escala apenas con volumen
B5: Infraestructura IA | C5: Asistente conceptual LLM (base) | D5: Asistente de repaso y overhead por reintentos | E5: 55 | F5: 55 | G5: 60 | H5: 65 | I5: 70 | J5: Escala apenas con volumen
B6: Costos Ocultos (Admin) | C6: Honorarios Contables | D6: Liquidación impositiva y comisiones | E6: 150 | F6: 150 | G6: 150 | H6: 150 | I6: 150 | J6: Necesario desde el día 1, no escala
B7: Administrativo | C7: Renovación de Dominio | D7: Renovación .com.ar: $8.500/año (NIC Argentina) / BNA $1.535 / 12 | E7: =8500/1535/12 -> 0.46145494 | F7: =8500/1535/12 -> 0.46145494 | G7: =8500/1535/12 -> 0.46145494 | H7: =8500/1535/12 -> 0.46145494 | I7: =8500/1535/12 -> 0.46145494
B8: Marketing | C8: Adquisición de Usuarios | D8: Redes sociales, pauta paga, referidos | E8: 40 | F8: 50 | G8: 60 | H8: 70 | I8: 80 | J8: Presupuesto modesto y estable, acorde a una demanda que oscila sin escalar
C9: TOTAL MENSUAL | E9: =E2+E3+E4+E5+E6+E7+E8 -> 374.46145 | F9: =F2+F3+F4+F5+F6+F7+F8 -> 384.46145 | G9: =G2+G3+G4+G5+G6+G7+G8 -> 409.46145 | H9: =H2+H3+H4+H5+H6+H7+H8 -> 434.46145 | I9: =I2+I3+I4+I5+I6+I7+I8 -> 459.46145
C10: TOTAL ANUAL (costos fijos) | E10: =E9*12 -> 4493.5375 | F10: =F9*12 -> 4613.5375 | G10: =G9*12 -> 4913.5375 | H10: =H9*12 -> 5213.5375 | I10: =I9*12 -> 5513.5375

Sheet Valor de Venta
B1: Categoría | C1: Item | D1: Detalle | E1: Unidad_o_Frecuencia | F1: Valor_Unitario | G1: Total_Estimado | H1: Observaciones
B2: Monetización | C2: Comisión de Plataforma (Take-rate) | D2: Modelo Escrow mediante MercadoPago | E2: Por transacción | F2: 0.27 | G2: =F2 -> 0.27 | H2: Competitivo (Preply cobra 18-33%)
B3: Monetización | C3: Ticket Promedio por Sesión | D3: Precio por hora (mediana de la encuesta, USD 4,56) x duración promedio / 60 | E3: Por clase | F3: =ROUND(4.56*F7/60,2) -> 3.88 | G3: =F3 -> 3.88 | H3: Piso de USD 4/h. Mediana de disposición a pagar de la encuesta (n=88), convertida con BNA vendedor $1.535/USD al 09/09/2026
B4: Monetización | C4: Comisión Bruta por Sesión | D4: Ticket x take-rate | E4: Por clase | F4: =F3*F2 -> 1.0476 | G4: =F4 -> 1.0476
B5: Costos Ocultos (IA) | C5: Duración de Sesión Estándar | D5: Sesión completa (paga full) | E5: Minutos | F5: 60 | G5: =F5 -> 60 | H5: Referencia sobre la que se calibra el costo de IA/procesamiento por hora
B6: Costos Ocultos (IA) | C6: % de Sesiones de 30 min (mínimo) | D6: Clases exprés / repaso corto | E6: % del total | F6: 0.3 | G6: =F6 -> 0.3 | H6: Supuesto editable: proporción de clases que usan el mínimo de 30 min en vez de la hora completa
B7: Costos Ocultos (IA) | C7: Duración Promedio Ponderada | D7: 60 min x (1-%30min) + 30 min x %30min | E7: Minutos | F7: =$F$5*(1-$F$6)+30*$F$6 -> 51 | G7: =F7 -> 51 | H7: Duración real promedio de una sesión, mezclando las de 60 y las de 30 minutos
B8: Costos Ocultos (IA) | C8: Costo del Resumen Opcional por Hora de Audio | D8: Egress solo audio LiveKit (USD 0,005/min x 60) + Gemini 3.5 Flash-Lite (32 tokens/s x 3.600 s x USD 0,30/M) | E8: Por hora | F8: =0.005*60+32*3600*0.3/1000000 -> 0.33456 | G8: =F8 -> 0.33456 | H8: Tarifas públicas de LiveKit Cloud y Gemini API, sep-2026
B9: Costos Ocultos (IA) | C9: Costo del Resumen Opcional por Sesión | D9: Costo/hora x duración promedio / 60 + salida (~1.500 tokens x USD 2,50/M) | E9: Por clase | F9: =$F$8*($F$7/60)+1500*2.5/1000000 -> 0.288126 | G9: =F9 -> 0.288126 | H9: Se cobra aparte como adicional opcional (filas 14 a 16)
B10: Costos Ocultos (Financieros) | C10: Tasa Pasarela de Pago (MercadoPago, c/IVA) | D10: Comisión de cobro ~4,99% + 21% IVA sobre esa comisión | E10: Por transacción | F10: 0.0604 | G10: =F10 -> 0.0604 | H10: Agregado: faltaba por completo en el modelo. Es un costo real de cobrar con MercadoPago, distinto de tu comisión de plataforma (que es ingreso, no costo).
B11: Costos Ocultos (Financieros) | C11: Costo Pasarela de Pago por Sesión | D11: Ticket x tasa de pasarela | E11: Por clase | F11: =F3*F10 -> 0.234352 | G11: =F11 -> 0.234352
B12: Monetización | C12: Margen Neto por Sesión | D12: Comisión bruta - costo pasarela de pago + margen del resumen opcional | E12: Por clase | F12: =F4-F11+F16 -> 0.8859176 | G12: =F12 -> 0.8859176 | H12: Impulsa los ingresos del flujo de fondos
B13: Costos Ocultos (Financieros) | C13: Fricción Financiera Adicional | D13: Retenciones IIBB, IVA, contracargos | E13: Por transacción | F13: Variable | G13: Variable | H13: No cuantificada (depende de jurisdicción); tratar como sensibilidad adicional sobre el margen
B14: Monetización | C14: Precio del Resumen Opcional | D14: Adicional por sesión, cobrado al alumno | E14: Por sesión | F14: 0.5 | G14: =F14 -> 0.5 | H14: Supuesto: cubre el costo y la pasarela (mínimo USD 0,31)
B15: Monetización | C15: Adopción del Resumen Opcional | D15: Proporción de sesiones que lo contratan | E15: % del total | F15: 0.4 | G15: =F15 -> 0.4 | H15: Supuesto declarado; el 56,8% de los encuestados valoró la función
B16: Monetización | C16: Margen del Resumen por Sesión Promedio | D16: Adopción x (precio x (1 - tasa pasarela) - costo) | E16: Por clase | F16: =F15*(F14*(1-F10)-F9) -> 0.0726696 | G16: =F16 -> 0.0726696 | H16: Se suma al margen neto por sesión

Sheet Estimación de Demanda
B1: Supuestos de Demanda
B2: Los alumnos activos por año son un insumo directo por escenario (celdas azules abajo), no una curva de crecimiento compuesto: reflejan estacionalidad académica, altas y bajas de cohortes, y el efecto puntual de campañas de marketing.
B3: Clases promedio por alumno por mes | F3: 3
B8: Escenario | C8: Métrica | D8: Año 1 | E8: Año 2 | F8: Año 3 | G8: Año 4 | H8: Año 5
B9: Pesimista | C9: Alumnos activos | D9: 130 | E9: 110 | F9: 160 | G9: 140 | H9: 190
C10: Clases anuales (sesiones) | D10: =D9*$F$3*12 -> 4680 | E10: =E9*$F$3*12 -> 3960 | F10: =F9*$F$3*12 -> 5760 | G10: =G9*$F$3*12 -> 5040 | H10: =H9*$F$3*12 -> 6840
B12: Base | C12: Alumnos activos | D12: 200 | E12: 260 | F12: 210 | G12: 290 | H12: 250
C13: Clases anuales (sesiones) | D13: =D12*$F$3*12 -> 7200 | E13: =E12*$F$3*12 -> 9360 | F13: =F12*$F$3*12 -> 7560 | G13: =G12*$F$3*12 -> 10440 | H13: =H12*$F$3*12 -> 9000
B15: Optimista | C15: Alumnos activos | D15: 280 | E15: 420 | F15: 340 | G15: 480 | H15: 400
C16: Clases anuales (sesiones) | D16: =D15*$F$3*12 -> 10080 | E16: =E15*$F$3*12 -> 15120 | F16: =F15*$F$3*12 -> 12240 | G16: =G15*$F$3*12 -> 17280 | H16: =H15*$F$3*12 -> 14400

Sheet VAN, TIR y Repago
B1: Flujo de Fondos y Evaluación Financiera (VAN, TIR, Payback)
B3: Tasa de Descuento (WACC / costo de oportunidad anual) | F3: =0.0483+1.55*0.0423+0.0971 -> 0.210965
B4: Inversión Inicial (Año 0) | F4: =-'Inversión Inicial'!$H$10 -> -4395.4706
B5: Margen Neto por Sesión (USD) | F5: ='Valor de Venta'!$F$12 -> 0.8859176
B6: Tasa = Tesoro EE.UU. 10 años (4,83%, FRED, 09/09/2026) + beta Software (Internet) 1,55 x ERP maduro 4,23% + riesgo país Argentina 9,71% (Damodaran, enero 2026)
B8: Escenario: Pesimista
B9: Período | C9: Año 0 | D9: Año 1 | E9: Año 2 | F9: Año 3 | G9: Año 4 | H9: Año 5
B10: Clases anuales (sesiones) | C10: 0 | D10: ='Estimación de Demanda'!D10 -> 4680 | E10: ='Estimación de Demanda'!E10 -> 3960 | F10: ='Estimación de Demanda'!F10 -> 5760 | G10: ='Estimación de Demanda'!G10 -> 5040 | H10: ='Estimación de Demanda'!H10 -> 6840
B11: Ingresos Netos (Clases x Margen Neto) | C11: 0 | D11: =D10*$F$5 -> 4146.0944 | E11: =E10*$F$5 -> 3508.2337 | F11: =F10*$F$5 -> 5102.8854 | G11: =G10*$F$5 -> 4465.0247 | H11: =H10*$F$5 -> 6059.6764
B12: Costos Fijos Anuales | C12: 0 | D12: =-'Gastos Post-lanzamiento'!E10 -> -4493.5375 | E12: =-'Gastos Post-lanzamiento'!F10 -> -4613.5375 | F12: =-'Gastos Post-lanzamiento'!G10 -> -4913.5375 | G12: =-'Gastos Post-lanzamiento'!H10 -> -5213.5375 | H12: =-'Gastos Post-lanzamiento'!I10 -> -5513.5375
B13: Flujo Neto de Fondos | C13: =$F$4 -> -4395.4706 | D13: =D11+D12 -> -347.44309 | E13: =E11+E12 -> -1105.3038 | F13: =F11+F12 -> 189.34792 | G13: =G11+G12 -> -748.51276 | H13: =H11+H12 -> 546.13892
B14: Flujo Acumulado | C14: =C13 -> -4395.4706 | D14: =C14+D13 -> -4742.9137 | E14: =D14+E13 -> -5848.2174 | F14: =E14+F13 -> -5658.8695 | G14: =F14+G13 -> -6407.3823 | H14: =G14+H13 -> -5861.2434
B15: Flujo Neto Descontado | C15: =C13/(1+$F$3)^0 -> -4395.4706 | D15: =D13/(1+$F$3)^1 -> -286.91423 | E15: =E13/(1+$F$3)^2 -> -753.73463 | F15: =F13/(1+$F$3)^3 -> 106.62665 | G15: =G13/(1+$F$3)^4 -> -348.07501 | H15: =H13/(1+$F$3)^5 -> 209.72257
B16: Flujo Acumulado Descontado | C16: =C15 -> -4395.4706 | D16: =C16+D15 -> -4682.3848 | E16: =D16+E15 -> -5436.1194 | F16: =E16+F15 -> -5329.4928 | G16: =F16+G15 -> -5677.5678 | H16: =G16+H15 -> -5467.8452
B18: Indicadores
B19: VAN (Valor Actual Neto) | D19: =NPV($F$3,D13:H13)+C13 -> -5467.8452
B20: TIR (Tasa Interna de Retorno) | D20: =IFERROR(IRR(C13:H13),"N/A") -> -0.52855795
B21: Período de Repago Simple (años) | D21: =IF(COUNTIF(C14:H14,"<0")=6,"No se recupera en 5 años",IFERROR((COUNTIF(C14:H14,"<0")-1)+(-INDEX(C14:H14,COUNTIF(C14:H14,"<0")))/INDEX(C13:H13,COUNTIF(C14:H14,"<0")+1),"N/A")) -> No se recupera en 5 años
B22: Período de Repago Descontado (años) | D22: =IF(COUNTIF(C16:H16,"<0")=6,"No se recupera en 5 años",IFERROR((COUNTIF(C16:H16,"<0")-1)+(-INDEX(C16:H16,COUNTIF(C16:H16,"<0")))/INDEX(C15:H15,COUNTIF(C16:H16,"<0")+1),"N/A")) -> No se recupera en 5 años
B24: Escenario: Base
B25: Período | C25: Año 0 | D25: Año 1 | E25: Año 2 | F25: Año 3 | G25: Año 4 | H25: Año 5
B26: Clases anuales (sesiones) | C26: 0 | D26: ='Estimación de Demanda'!D13 -> 7200 | E26: ='Estimación de Demanda'!E13 -> 9360 | F26: ='Estimación de Demanda'!F13 -> 7560 | G26: ='Estimación de Demanda'!G13 -> 10440 | H26: ='Estimación de Demanda'!H13 -> 9000
B27: Ingresos Netos (Clases x Margen Neto) | C27: 0 | D27: =D26*$F$5 -> 6378.6067 | E27: =E26*$F$5 -> 8292.1887 | F27: =F26*$F$5 -> 6697.5371 | G27: =G26*$F$5 -> 9248.9797 | H27: =H26*$F$5 -> 7973.2584
B28: Costos Fijos Anuales | C28: 0 | D28: =-'Gastos Post-lanzamiento'!E10 -> -4493.5375 | E28: =-'Gastos Post-lanzamiento'!F10 -> -4613.5375 | F28: =-'Gastos Post-lanzamiento'!G10 -> -4913.5375 | G28: =-'Gastos Post-lanzamiento'!H10 -> -5213.5375 | H28: =-'Gastos Post-lanzamiento'!I10 -> -5513.5375
B29: Flujo Neto de Fondos | C29: =$F$4 -> -4395.4706 | D29: =D27+D28 -> 1885.0693 | E29: =E27+E28 -> 3678.6513 | F29: =F27+F28 -> 1783.9996 | G29: =G27+G28 -> 4035.4423 | H29: =H27+H28 -> 2459.7209
B30: Flujo Acumulado | C30: =C29 -> -4395.4706 | D30: =C30+D29 -> -2510.4013 | E30: =D30+E29 -> 1168.2499 | F30: =E30+F29 -> 2952.2495 | G30: =F30+G29 -> 6987.6918 | H30: =G30+H29 -> 9447.4128
B31: Flujo Neto Descontado | C31: =C29/(1+$F$3)^0 -> -4395.4706 | D31: =D29/(1+$F$3)^1 -> 1556.667 | E31: =E29/(1+$F$3)^2 -> 2508.5655 | F31: =F29/(1+$F$3)^3 -> 1004.6157 | G31: =G29/(1+$F$3)^4 -> 1876.57 | H31: =H29/(1+$F$3)^5 -> 944.55637
B32: Flujo Acumulado Descontado | C32: =C31 -> -4395.4706 | D32: =C32+D31 -> -2838.8036 | E32: =D32+E31 -> -330.23812 | F32: =E32+F31 -> 674.37762 | G32: =F32+G31 -> 2550.9476 | H32: =G32+H31 -> 3495.504
B34: Indicadores
B35: VAN (Valor Actual Neto) | D35: =NPV($F$3,D29:H29)+C29 -> 3495.504
B36: TIR (Tasa Interna de Retorno) | D36: =IFERROR(IRR(C29:H29),"N/A") -> 0.52059021
B37: Período de Repago Simple (años) | D37: =IF(COUNTIF(C30:H30,"<0")=6,"No se recupera en 5 años",IFERROR((COUNTIF(C30:H30,"<0")-1)+(-INDEX(C30:H30,COUNTIF(C30:H30,"<0")))/INDEX(C29:H29,COUNTIF(C30:H30,"<0")+1),"N/A")) -> 1.6824244
B38: Período de Repago Descontado (años) | D38: =IF(COUNTIF(C32:H32,"<0")=6,"No se recupera en 5 años",IFERROR((COUNTIF(C32:H32,"<0")-1)+(-INDEX(C32:H32,COUNTIF(C32:H32,"<0")))/INDEX(C31:H31,COUNTIF(C32:H32,"<0")+1),"N/A")) -> 2.3287208
B40: Escenario: Optimista
B41: Período | C41: Año 0 | D41: Año 1 | E41: Año 2 | F41: Año 3 | G41: Año 4 | H41: Año 5
B42: Clases anuales (sesiones) | C42: 0 | D42: ='Estimación de Demanda'!D16 -> 10080 | E42: ='Estimación de Demanda'!E16 -> 15120 | F42: ='Estimación de Demanda'!F16 -> 12240 | G42: ='Estimación de Demanda'!G16 -> 17280 | H42: ='Estimación de Demanda'!H16 -> 14400
B43: Ingresos Netos (Clases x Margen Neto) | C43: 0 | D43: =D42*$F$5 -> 8930.0494 | E43: =E42*$F$5 -> 13395.074 | F43: =F42*$F$5 -> 10843.631 | G43: =G42*$F$5 -> 15308.656 | H43: =H42*$F$5 -> 12757.213
B44: Costos Fijos Anuales | C44: 0 | D44: =-'Gastos Post-lanzamiento'!E10 -> -4493.5375 | E44: =-'Gastos Post-lanzamiento'!F10 -> -4613.5375 | F44: =-'Gastos Post-lanzamiento'!G10 -> -4913.5375 | G44: =-'Gastos Post-lanzamiento'!H10 -> -5213.5375 | H44: =-'Gastos Post-lanzamiento'!I10 -> -5513.5375
B45: Flujo Neto de Fondos | C45: =$F$4 -> -4395.4706 | D45: =D43+D44 -> 4436.5119 | E45: =E43+E44 -> 8781.5367 | F45: =F43+F44 -> 5930.094 | G45: =G43+G44 -> 10095.119 | H45: =H43+H44 -> 7243.676
B46: Flujo Acumulado | C46: =C45 -> -4395.4706 | D46: =C46+D45 -> 41.04136 | E46: =D46+E45 -> 8822.578 | F46: =E46+F45 -> 14752.672 | G46: =F46+G45 -> 24847.791 | H46: =G46+H45 -> 32091.467
...
